<?xml version="1.0" encoding="UTF-8"?>
<testng-results ignored="0" total="3" passed="2" failed="1" skipped="0">
  <reporter-output>
    <line>
      <![CDATA[Hi I am running From TC1]]>
    </line>
    <line>
      <![CDATA[Hi I am running From TC3]]>
    </line>
  </reporter-output>
  <suite started-at="2022-08-26T14:13:37 IST" name="Default suite" finished-at="2022-08-26T14:13:37 IST" duration-ms="152">
    <groups>
    </groups>
    <test started-at="2022-08-26T14:13:37 IST" name="Default test" finished-at="2022-08-26T14:13:37 IST" duration-ms="152">
      <class name="TestNG_Program.TestNG_Class2">
        <test-method signature="Tc1()[pri:0, instance:TestNG_Program.TestNG_Class2@61df66b6]" started-at="2022-08-26T14:13:37 IST" name="Tc1" finished-at="2022-08-26T14:13:37 IST" duration-ms="19" status="PASS">
          <reporter-output>
            <line>
              <![CDATA[Hi I am running From TC1]]>
            </line>
          </reporter-output>
        </test-method> <!-- Tc1 -->
        <test-method signature="Tc2()[pri:0, instance:TestNG_Program.TestNG_Class2@61df66b6]" started-at="2022-08-26T14:13:37 IST" name="Tc2" finished-at="2022-08-26T14:13:37 IST" duration-ms="54" status="FAIL">
          <exception class="java.lang.AssertionError">
            <message>
              <![CDATA[null]]>
            </message>
            <full-stacktrace>
              <![CDATA[java.lang.AssertionError: null
at org.testng.Assert.fail(Assert.java:99)
at org.testng.Assert.fail(Assert.java:106)
at TestNG_Program.TestNG_Class2.Tc2(TestNG_Class2.java:16)
at java.base/jdk.internal.reflect.DirectMethodHandleAccessor.invoke(DirectMethodHandleAccessor.java:104)
at java.base/java.lang.reflect.Method.invoke(Method.java:577)
at org.testng.internal.MethodInvocationHelper.invokeMethod(MethodInvocationHelper.java:133)
at org.testng.internal.TestInvoker.invokeMethod(TestInvoker.java:598)
at org.testng.internal.TestInvoker.invokeTestMethod(TestInvoker.java:173)
at org.testng.internal.MethodRunner.runInSequence(MethodRunner.java:46)
at org.testng.internal.TestInvoker$MethodInvocationAgent.invoke(TestInvoker.java:824)
at org.testng.internal.TestInvoker.invokeTestMethods(TestInvoker.java:146)
at org.testng.internal.TestMethodWorker.invokeTestMethods(TestMethodWorker.java:146)
at org.testng.internal.TestMethodWorker.run(TestMethodWorker.java:128)
at java.base/java.util.ArrayList.forEach(ArrayList.java:1511)
at org.testng.TestRunner.privateRun(TestRunner.java:794)
at org.testng.TestRunner.run(TestRunner.java:596)
at org.testng.SuiteRunner.runTest(SuiteRunner.java:377)
at org.testng.SuiteRunner.runSequentially(SuiteRunner.java:371)
at org.testng.SuiteRunner.privateRun(SuiteRunner.java:332)
at org.testng.SuiteRunner.run(SuiteRunner.java:276)
at org.testng.SuiteRunnerWorker.runSuite(SuiteRunnerWorker.java:53)
at org.testng.SuiteRunnerWorker.run(SuiteRunnerWorker.java:96)
at org.testng.TestNG.runSuitesSequentially(TestNG.java:1212)
at org.testng.TestNG.runSuitesLocally(TestNG.java:1134)
at org.testng.TestNG.runSuites(TestNG.java:1063)
at org.testng.TestNG.run(TestNG.java:1031)
at org.testng.remote.AbstractRemoteTestNG.run(AbstractRemoteTestNG.java:115)
at org.testng.remote.RemoteTestNG.initAndRun(RemoteTestNG.java:251)
at org.testng.remote.RemoteTestNG.main(RemoteTestNG.java:77)
]]>
            </full-stacktrace>
          </exception> <!-- java.lang.AssertionError -->
          <reporter-output>
          </reporter-output>
        </test-method> <!-- Tc2 -->
        <test-method signature="Tc3()[pri:0, instance:TestNG_Program.TestNG_Class2@61df66b6]" started-at="2022-08-26T14:13:37 IST" name="Tc3" finished-at="2022-08-26T14:13:37 IST" duration-ms="3" status="PASS">
          <reporter-output>
            <line>
              <![CDATA[Hi I am running From TC3]]>
            </line>
          </reporter-output>
        </test-method> <!-- Tc3 -->
      </class> <!-- TestNG_Program.TestNG_Class2 -->
    </test> <!-- Default test -->
  </suite> <!-- Default suite -->
</testng-results>
